{
 "cells": [
  {
   "cell_type": "code",
   "execution_count": 1,
   "metadata": {},
   "outputs": [],
   "source": [
    "import rasterio\n",
    "import sys\n",
    "import time"
   ]
  },
  {
   "cell_type": "code",
   "execution_count": 2,
   "metadata": {},
   "outputs": [],
   "source": [
    "def _warp_two(warpfile):\n",
    "    \n",
    "            with rasterio.open(warpfile) as src:\n",
    "                print(type(src))\n",
    "        "
   ]
  },
  {
   "cell_type": "code",
   "execution_count": 3,
   "metadata": {},
   "outputs": [],
   "source": [
    "def _warp_one(warpfile):\n",
    "    cnt=10;\n",
    "    while (cnt>0):\n",
    "        try:     \n",
    "            with rasterio.open(warpfile) as src:\n",
    "                print(type(src))\n",
    "            break\n",
    "        except rasterio.errors.RasterioIOError:\n",
    "            print(\"Unexpected error:\", sys.exc_info()[0])\n",
    "            print('oops',cnt)\n",
    "            cnt = cnt - 1\n",
    "            time.sleep(4)\n",
    "            \n"
   ]
  },
  {
   "cell_type": "code",
   "execution_count": 4,
   "metadata": {},
   "outputs": [],
   "source": [
    "filename='/vsis3/dev-et-data/in/USA_data/NDVI_med2003_2017/med366.250_m_NDVI.tif'"
   ]
  },
  {
   "cell_type": "code",
   "execution_count": 5,
   "metadata": {},
   "outputs": [
    {
     "name": "stdout",
     "output_type": "stream",
     "text": [
      "<class 'rasterio.io.DatasetReader'>\n"
     ]
    }
   ],
   "source": [
    "_warp_two(filename)"
   ]
  },
  {
   "cell_type": "code",
   "execution_count": 6,
   "metadata": {},
   "outputs": [
    {
     "name": "stdout",
     "output_type": "stream",
     "text": [
      "<class 'rasterio.io.DatasetReader'>\n"
     ]
    }
   ],
   "source": [
    "_warp_one(filename)"
   ]
  },
  {
   "cell_type": "code",
   "execution_count": 7,
   "metadata": {},
   "outputs": [],
   "source": [
    "filename='/vsis3/dev-et-data/in/USA_data/NDVI_med2003_2017/med366.250_m_NDVI.gif'"
   ]
  },
  {
   "cell_type": "code",
   "execution_count": 8,
   "metadata": {},
   "outputs": [
    {
     "name": "stdout",
     "output_type": "stream",
     "text": [
      "Unexpected error: <class 'rasterio.errors.RasterioIOError'>\n",
      "oops 10\n",
      "Unexpected error: <class 'rasterio.errors.RasterioIOError'>\n",
      "oops 9\n",
      "Unexpected error: <class 'rasterio.errors.RasterioIOError'>\n",
      "oops 8\n",
      "Unexpected error: <class 'rasterio.errors.RasterioIOError'>\n",
      "oops 7\n",
      "Unexpected error: <class 'rasterio.errors.RasterioIOError'>\n",
      "oops 6\n",
      "Unexpected error: <class 'rasterio.errors.RasterioIOError'>\n",
      "oops 5\n",
      "Unexpected error: <class 'rasterio.errors.RasterioIOError'>\n",
      "oops 4\n",
      "Unexpected error: <class 'rasterio.errors.RasterioIOError'>\n",
      "oops 3\n",
      "Unexpected error: <class 'rasterio.errors.RasterioIOError'>\n",
      "oops 2\n",
      "Unexpected error: <class 'rasterio.errors.RasterioIOError'>\n",
      "oops 1\n"
     ]
    }
   ],
   "source": [
    "_warp_one(filename)"
   ]
  },
  {
   "cell_type": "raw",
   "metadata": {},
   "source": []
  },
  {
   "cell_type": "code",
   "execution_count": 9,
   "metadata": {},
   "outputs": [
    {
     "ename": "RasterioIOError",
     "evalue": "'/vsis3/dev-et-data/in/USA_data/NDVI_med2003_2017/med366.250_m_NDVI.gif' does not exist in the file system, and is not recognized as a supported dataset name.",
     "output_type": "error",
     "traceback": [
      "\u001b[0;31m---------------------------------------------------------------------------\u001b[0m",
      "\u001b[0;31mCPLE_OpenFailedError\u001b[0m                      Traceback (most recent call last)",
      "\u001b[0;32mrasterio/_base.pyx\u001b[0m in \u001b[0;36mrasterio._base.DatasetBase.__init__\u001b[0;34m()\u001b[0m\n",
      "\u001b[0;32mrasterio/_shim.pyx\u001b[0m in \u001b[0;36mrasterio._shim.open_dataset\u001b[0;34m()\u001b[0m\n",
      "\u001b[0;32mrasterio/_err.pyx\u001b[0m in \u001b[0;36mrasterio._err.exc_wrap_pointer\u001b[0;34m()\u001b[0m\n",
      "\u001b[0;31mCPLE_OpenFailedError\u001b[0m: '/vsis3/dev-et-data/in/USA_data/NDVI_med2003_2017/med366.250_m_NDVI.gif' does not exist in the file system, and is not recognized as a supported dataset name.",
      "\nDuring handling of the above exception, another exception occurred:\n",
      "\u001b[0;31mRasterioIOError\u001b[0m                           Traceback (most recent call last)",
      "\u001b[0;32m<ipython-input-9-fb1fcdeccfc4>\u001b[0m in \u001b[0;36m<module>\u001b[0;34m\u001b[0m\n\u001b[0;32m----> 1\u001b[0;31m \u001b[0m_warp_two\u001b[0m\u001b[0;34m(\u001b[0m\u001b[0mfilename\u001b[0m\u001b[0;34m)\u001b[0m\u001b[0;34m\u001b[0m\u001b[0;34m\u001b[0m\u001b[0m\n\u001b[0m",
      "\u001b[0;32m<ipython-input-2-8d67560ff749>\u001b[0m in \u001b[0;36m_warp_two\u001b[0;34m(warpfile)\u001b[0m\n\u001b[1;32m      1\u001b[0m \u001b[0;32mdef\u001b[0m \u001b[0m_warp_two\u001b[0m\u001b[0;34m(\u001b[0m\u001b[0mwarpfile\u001b[0m\u001b[0;34m)\u001b[0m\u001b[0;34m:\u001b[0m\u001b[0;34m\u001b[0m\u001b[0;34m\u001b[0m\u001b[0m\n\u001b[1;32m      2\u001b[0m \u001b[0;34m\u001b[0m\u001b[0m\n\u001b[0;32m----> 3\u001b[0;31m             \u001b[0;32mwith\u001b[0m \u001b[0mrasterio\u001b[0m\u001b[0;34m.\u001b[0m\u001b[0mopen\u001b[0m\u001b[0;34m(\u001b[0m\u001b[0mwarpfile\u001b[0m\u001b[0;34m)\u001b[0m \u001b[0;32mas\u001b[0m \u001b[0msrc\u001b[0m\u001b[0;34m:\u001b[0m\u001b[0;34m\u001b[0m\u001b[0;34m\u001b[0m\u001b[0m\n\u001b[0m\u001b[1;32m      4\u001b[0m                 \u001b[0mprint\u001b[0m\u001b[0;34m(\u001b[0m\u001b[0mtype\u001b[0m\u001b[0;34m(\u001b[0m\u001b[0msrc\u001b[0m\u001b[0;34m)\u001b[0m\u001b[0;34m)\u001b[0m\u001b[0;34m\u001b[0m\u001b[0;34m\u001b[0m\u001b[0m\n\u001b[1;32m      5\u001b[0m \u001b[0;34m\u001b[0m\u001b[0m\n",
      "\u001b[0;32m/opt/tljh/user/lib/python3.7/site-packages/rasterio/env.py\u001b[0m in \u001b[0;36mwrapper\u001b[0;34m(*args, **kwds)\u001b[0m\n\u001b[1;32m    432\u001b[0m \u001b[0;34m\u001b[0m\u001b[0m\n\u001b[1;32m    433\u001b[0m         \u001b[0;32mwith\u001b[0m \u001b[0menv_ctor\u001b[0m\u001b[0;34m(\u001b[0m\u001b[0msession\u001b[0m\u001b[0;34m=\u001b[0m\u001b[0msession\u001b[0m\u001b[0;34m)\u001b[0m\u001b[0;34m:\u001b[0m\u001b[0;34m\u001b[0m\u001b[0;34m\u001b[0m\u001b[0m\n\u001b[0;32m--> 434\u001b[0;31m             \u001b[0;32mreturn\u001b[0m \u001b[0mf\u001b[0m\u001b[0;34m(\u001b[0m\u001b[0;34m*\u001b[0m\u001b[0margs\u001b[0m\u001b[0;34m,\u001b[0m \u001b[0;34m**\u001b[0m\u001b[0mkwds\u001b[0m\u001b[0;34m)\u001b[0m\u001b[0;34m\u001b[0m\u001b[0;34m\u001b[0m\u001b[0m\n\u001b[0m\u001b[1;32m    435\u001b[0m \u001b[0;34m\u001b[0m\u001b[0m\n\u001b[1;32m    436\u001b[0m     \u001b[0;32mreturn\u001b[0m \u001b[0mwrapper\u001b[0m\u001b[0;34m\u001b[0m\u001b[0;34m\u001b[0m\u001b[0m\n",
      "\u001b[0;32m/opt/tljh/user/lib/python3.7/site-packages/rasterio/__init__.py\u001b[0m in \u001b[0;36mopen\u001b[0;34m(fp, mode, driver, width, height, count, crs, transform, dtype, nodata, sharing, **kwargs)\u001b[0m\n\u001b[1;32m    217\u001b[0m         \u001b[0;31m# None.\u001b[0m\u001b[0;34m\u001b[0m\u001b[0;34m\u001b[0m\u001b[0;34m\u001b[0m\u001b[0m\n\u001b[1;32m    218\u001b[0m         \u001b[0;32mif\u001b[0m \u001b[0mmode\u001b[0m \u001b[0;34m==\u001b[0m \u001b[0;34m'r'\u001b[0m\u001b[0;34m:\u001b[0m\u001b[0;34m\u001b[0m\u001b[0;34m\u001b[0m\u001b[0m\n\u001b[0;32m--> 219\u001b[0;31m             \u001b[0ms\u001b[0m \u001b[0;34m=\u001b[0m \u001b[0mDatasetReader\u001b[0m\u001b[0;34m(\u001b[0m\u001b[0mpath\u001b[0m\u001b[0;34m,\u001b[0m \u001b[0mdriver\u001b[0m\u001b[0;34m=\u001b[0m\u001b[0mdriver\u001b[0m\u001b[0;34m,\u001b[0m \u001b[0msharing\u001b[0m\u001b[0;34m=\u001b[0m\u001b[0msharing\u001b[0m\u001b[0;34m,\u001b[0m \u001b[0;34m**\u001b[0m\u001b[0mkwargs\u001b[0m\u001b[0;34m)\u001b[0m\u001b[0;34m\u001b[0m\u001b[0;34m\u001b[0m\u001b[0m\n\u001b[0m\u001b[1;32m    220\u001b[0m         \u001b[0;32melif\u001b[0m \u001b[0mmode\u001b[0m \u001b[0;34m==\u001b[0m \u001b[0;34m'r+'\u001b[0m\u001b[0;34m:\u001b[0m\u001b[0;34m\u001b[0m\u001b[0;34m\u001b[0m\u001b[0m\n\u001b[1;32m    221\u001b[0m             \u001b[0ms\u001b[0m \u001b[0;34m=\u001b[0m \u001b[0mget_writer_for_path\u001b[0m\u001b[0;34m(\u001b[0m\u001b[0mpath\u001b[0m\u001b[0;34m)\u001b[0m\u001b[0;34m(\u001b[0m\u001b[0mpath\u001b[0m\u001b[0;34m,\u001b[0m \u001b[0mmode\u001b[0m\u001b[0;34m,\u001b[0m \u001b[0mdriver\u001b[0m\u001b[0;34m=\u001b[0m\u001b[0mdriver\u001b[0m\u001b[0;34m,\u001b[0m \u001b[0msharing\u001b[0m\u001b[0;34m=\u001b[0m\u001b[0msharing\u001b[0m\u001b[0;34m,\u001b[0m \u001b[0;34m**\u001b[0m\u001b[0mkwargs\u001b[0m\u001b[0;34m)\u001b[0m\u001b[0;34m\u001b[0m\u001b[0;34m\u001b[0m\u001b[0m\n",
      "\u001b[0;32mrasterio/_base.pyx\u001b[0m in \u001b[0;36mrasterio._base.DatasetBase.__init__\u001b[0;34m()\u001b[0m\n",
      "\u001b[0;31mRasterioIOError\u001b[0m: '/vsis3/dev-et-data/in/USA_data/NDVI_med2003_2017/med366.250_m_NDVI.gif' does not exist in the file system, and is not recognized as a supported dataset name."
     ]
    }
   ],
   "source": [
    "_warp_two(filename)"
   ]
  },
  {
   "cell_type": "code",
   "execution_count": null,
   "metadata": {},
   "outputs": [],
   "source": []
  }
 ],
 "metadata": {
  "kernelspec": {
   "display_name": "Python 3",
   "language": "python",
   "name": "python3"
  },
  "language_info": {
   "codemirror_mode": {
    "name": "ipython",
    "version": 3
   },
   "file_extension": ".py",
   "mimetype": "text/x-python",
   "name": "python",
   "nbconvert_exporter": "python",
   "pygments_lexer": "ipython3",
   "version": "3.7.3"
  }
 },
 "nbformat": 4,
 "nbformat_minor": 4
}
